<?xml version="1.0" ?>
<!-- =================================================================================== -->
<!-- |    This document was autogenerated by xacro from euler.xacro                    | -->
<!-- |    EDITING THIS FILE BY HAND IS NOT RECOMMENDED                                 | -->
<!-- =================================================================================== -->
<robot name="euler" xmlns:xacro="http://ros.org/wiki/xacro">
  <link name="vetex_base_link">
    <visual>
      <origin rpy="0 0 0"/>
      <geometry>
        <mesh filename="package://vetex_support/meshes/visual/base_link.stl"/>
      </geometry>
      <material name="">
        <color rgba="0.75294 0.75294 0.75294 1"/>
      </material>
    </visual>
    <collision>
      <origin rpy="0 0 0" xyz="0 0 0"/>
      <geometry>
        <mesh filename="package://vetex_support/meshes/collision/base_link.stl"/>
      </geometry>
    </collision>
  </link>
  <link name="vetex_map">
    <visual>
      <origin rpy="0 0 0" xyz="0 0 0"/>
      <geometry>
        <mesh filename="package://vetex_support/meshes/visual/map.stl"/>
      </geometry>
      <material name="">
        <color rgba="0.75294 0.75294 0.75294 1"/>
      </material>
    </visual>
    <collision>
      <origin Rpy="0 0 0" xyz="0 0 0"/>
      <geometry>
        <mesh filename="package://vetex_support/meshes/collision/map.stl"/>
      </geometry>
    </collision>
  </link>
  <link name="vetex_odom">
    <visual>
      <origin rpy="0 0 0" xyz="0 0 0"/>
      <geometry>
        <mesh filename="package://vetex_support/meshes/visual/odom.stl"/>
      </geometry>
      <material name="">
        <color rgba="0.75294 0.75294 0.75294 1"/>
      </material>
    </visual>
    <collision>
      <origin rpy="0 0 0" xyz="0 0 0"/>
      <geometry>
        <mesh filename="package://vetex_support/meshes/collision/odom.stl"/>
      </geometry>
    </collision>
  </link>
  <link name="vetex_left_front_wheel">
    <visual>
      <origin rpy="0 0 0" xyz="0 0 0"/>
      <geometry>
        <mesh filename="package://vetex_support/meshes/visual/left_front_wheel.stl"/>
      </geometry>
      <material name="">
        <color rgba="0.75294 0.75294 0.75294 1"/>
      </material>
    </visual>
    <collision>
      <origin rpy="0 0 0" xyz="0 0 0"/>
      <geometry>
        <mesh filename="package://vetex_support/meshes/collision/left_front_wheel.stl"/>
      </geometry>
    </collision>
  </link>
  <link name="vetex_left_rear_wheel">
    <visual>
      <origin rpy="0 0 0" xyz="0 0 0"/>
      <geometry>
        <mesh filename="package://vetex_support/meshes/visual/left_rear_wheel.stl"/>
      </geometry>
      <material name="">
        <color rgba="0.75294 0.75294 0.75294 1"/>
      </material>
    </visual>
    <collision>
      <origin rpy="0 0 0" xyz="0 0 0"/>
      <geometry>
        <mesh filename="package://vetex_support/meshes/collision/left_rear_wheel.stl"/>
      </geometry>
    </collision>
  </link>
  <link name="vetex_right_rear_wheel">
    <visual>
      <origin rpy="3.1415 0 0" xyz="0 0 0"/>
      <geometry>
        <mesh filename="package://vetex_support/meshes/visual/right_rear_wheel.stl"/>
      </geometry>
      <material name="">
        <color rgba="0.75294 0.75294 0.75294 1"/>
      </material>
    </visual>
    <collision>
      <origin rpy="3.1415 0 0" xyz="0 0 0"/>
      <geometry>
        <mesh filename="package://vetex_support/meshes/collision/right_rear_wheel.stl"/>
      </geometry>
    </collision>
  </link>
  <link name="vetex_right_front_wheel">
    <visual>
      <origin rpy="3.1415 0 0" xyz="0 0 0"/>
      <geometry>
        <mesh filename="package://vetex_support/meshes/visual/right_front_wheel.stl"/>
      </geometry>
      <material name="">
        <color rgba="0.75294 0.75294 0.75294 1"/>
      </material>
    </visual>
    <collision>
      <origin rpy="3.1415 0 0" xyz="0 0 0"/>
      <geometry>
        <mesh filename="package://vetex_support/meshes/collision/right_front_wheel.stl"/>
      </geometry>
    </collision>
  </link>
  <joint name="vetex_map" type="fixed">
    <origin rpy="0 0 0" xyz="0 0 0"/>
    <parent link="vetex_base_link"/>
    <child link="vetex_map"/>
    <axis xyz="0 0 0"/>
  </joint>
  <joint name="vetex_odom" type="fixed">
    <origin rpy="0 0 0" xyz="0 0 0"/>
    <parent link="vetex_map"/>
    <child link="vetex_odom"/>
    <axis xyz="0 0 0"/>
  </joint>
  <joint name="vetex_left_front_wheel" type="revolute">
    <origin rpy="0 1 0" xyz="0 0.58668 0.21577"/>
    <parent link="vetex_odom"/>
    <child link="vetex_left_front_wheel"/>
    <axis xyz="0 1 0"/>
    <limit effort="0" lower="-10" upper="10" velocity="3"/>
  </joint>
  <joint name="vetex_left_rear_wheel" type="revolute">
    <origin rpy="0 1 0" xyz="-2.0878 0.58642 0.21577"/>
    <parent link="vetex_odom"/>
    <child link="vetex_left_rear_wheel"/>
    <axis xyz="0 1 0"/>
    <limit effort="0" lower="-10" upper="10" velocity="3"/>
  </joint>
  <joint name="vetex_right_rear_wheel" type="revolute">
    <origin rpy="0 1 0" xyz="-2.0878 -0.58668 0.21577"/>
    <parent link="vetex_odom"/>
    <child link="vetex_right_rear_wheel"/>
    <axis xyz="0 1 0"/>
    <limit effort="0" lower="-10" upper="10" velocity="3"/>
  </joint>
  <joint name="vetex_right_front_wheel" type="revolute">
    <origin rpy="0 0 0" xyz="0 -0.58642 0.21577"/>
    <parent link="vetex_odom"/>
    <child link="vetex_right_front_wheel"/>
    <axis xyz="0 1 0"/>
    <limit effort="0" lower="-10" upper="10" velocity="3"/>
  </joint>
  <link name="motoman_base_link">
    <visual>
      <origin rpy="0 0 0"/>
      <geometry>
        <mesh filename="package://motoman_mh5lf_support/meshes/mh5lf/visual/base_link.stl"/>
      </geometry>
      <material name="blue">
        <color rgba="0 0 1 1"/>
      </material>
    </visual>
    <collision>
      <origin rpy="0 0 0"/>
      <geometry>
        <mesh filename="package://motoman_mh5lf_support/meshes/mh5lf/collision/base_link.stl"/>
      </geometry>
      <material name="yellow">
        <color rgba="0 1 1 1"/>
      </material>
    </collision>
  </link>
  <link name="motoman_link_s">
    <visual>
      <geometry>
        <mesh filename="package://motoman_mh5lf_support/meshes/mh5lf/visual/link_s.stl"/>
      </geometry>
      <material name="silver">
        <color rgba="0.8 0.8 0.8 1"/>
      </material>
    </visual>
    <collision>
      <geometry>
        <mesh filename="package://motoman_mh5lf_support/meshes/mh5lf/collision/link_s.stl"/>
      </geometry>
      <material name="yellow"/>
    </collision>
  </link>
  <link name="motoman_link_l">
    <visual>
      <geometry>
        <mesh filename="package://motoman_mh5lf_support/meshes/mh5lf/visual/link_l.stl"/>
      </geometry>
      <material name="blue"/>
    </visual>
    <collision>
      <geometry>
        <mesh filename="package://motoman_mh5lf_support/meshes/mh5lf/collision/link_l.stl"/>
      </geometry>
      <material name="yellow"/>
    </collision>
  </link>
  <link name="motoman_link_u">
    <visual>
      <geometry>
        <mesh filename="package://motoman_mh5lf_support/meshes/mh5lf/visual/link_u.stl"/>
      </geometry>
      <material name="blue"/>
    </visual>
    <collision>
      <geometry>
        <mesh filename="package://motoman_mh5lf_support/meshes/mh5lf/collision/link_u.stl"/>
      </geometry>
      <material name="yellow"/>
    </collision>
  </link>
  <link name="motoman_link_r">
    <visual>
      <geometry>
        <mesh filename="package://motoman_mh5lf_support/meshes/mh5lf/visual/link_r.stl"/>
      </geometry>
      <material name="silver"/>
    </visual>
    <collision>
      <geometry>
        <mesh filename="package://motoman_mh5lf_support/meshes/mh5lf/collision/link_r.stl"/>
      </geometry>
      <material name="yellow"/>
    </collision>
  </link>
  <link name="motoman_link_b">
    <visual>
      <geometry>
        <mesh filename="package://motoman_mh5lf_support/meshes/mh5lf/visual/link_b.stl"/>
      </geometry>
      <material name="blue"/>
    </visual>
    <collision>
      <geometry>
        <mesh filename="package://motoman_mh5lf_support/meshes/mh5lf/collision/link_b.stl"/>
      </geometry>
      <material name="yellow"/>
    </collision>
  </link>
  <link name="motoman_link_t">
    <visual>
      <geometry>
        <mesh filename="package://motoman_mh5lf_support/meshes/mh5lf/visual/link_t.stl"/>
      </geometry>
      <material name="silver"/>
    </visual>
    <collision>
      <geometry>
        <mesh filename="package://motoman_mh5lf_support/meshes/mh5lf/collision/link_t.stl"/>
      </geometry>
      <material name="yellow"/>
    </collision>
  </link>
  <joint name="motoman_joint_s" type="revolute">
    <parent link="motoman_base_link"/>
    <child link="motoman_link_s"/>
    <origin rpy="0 0 0" xyz="0 0 0"/>
    <axis xyz="0 0 1"/>
    <limit effort="100" lower="-2.96697222222222" upper="2.96697222222222" velocity="4.71225"/>
  </joint>
  <joint name="motoman_joint_l" type="revolute">
    <parent link="motoman_link_s"/>
    <child link="motoman_link_l"/>
    <origin rpy="0 0 0" xyz="0.088 0 0.36"/>
    <axis xyz="0 1 0"/>
    <limit effort="100" lower="-1.13443055555556" upper="2.61791666666667" velocity="4.88677777777778"/>
  </joint>
  <joint name="motoman_joint_u" type="revolute">
    <parent link="motoman_link_l"/>
    <child link="motoman_link_u"/>
    <origin rpy="0 0 0" xyz="0 0 0.4"/>
    <axis xyz="0 -1 0"/>
    <limit effort="100" lower="-2.40848333333333" upper="4.45045833333333" velocity="5.23583333333333"/>
  </joint>
  <joint name="motoman_joint_r" type="revolute">
    <parent link="motoman_link_u"/>
    <child link="motoman_link_r"/>
    <origin rpy="0 0 0" xyz="0 0 0.04"/>
    <axis xyz="-1 0 0"/>
    <limit effort="100" lower="-3.31602777777778" upper="3.31602777777778" velocity="7.85375"/>
  </joint>
  <joint name="motoman_joint_b" type="revolute">
    <parent link="motoman_link_r"/>
    <child link="motoman_link_b"/>
    <origin rpy="0 0 0" xyz="0.404 0 0"/>
    <axis xyz="0 -1 0"/>
    <limit effort="100" lower="-2.356125" upper="2.356125" velocity="7.85375"/>
  </joint>
  <joint name="motoman_joint_t" type="revolute">
    <parent link="motoman_link_b"/>
    <child link="motoman_link_t"/>
    <origin rpy="0 0 0" xyz="0 0 0"/>
    <axis xyz="-1 0 0"/>
    <limit effort="100" lower="-6.283" upper="6.283" velocity="12.566"/>
  </joint>
  <property name="M_PI" value="3.14159"/>
  <link name="_bodycenter">
    <visual>
      <origin rpy="0 0 0" xyz="0 0 0 "/>
      <geometry>
        <mesh filename="package://euler_support/meshes/visual/asus_sensor.stl"/>
      </geometry>
      <material name="lt_black">
        <color rgba="0.3 0.3 0.3 1"/>
      </material>
    </visual>
    <collision>
      <origin rpy="0 0 0" xyz="0.0 0.0 0.0"/>
      <geometry>
        <box size="0.0730 0.2760 0.0720"/>
      </geometry>
    </collision>
  </link>
  <joint name="_base-bodycenter-prism-x" type="fixed">
    <origin rpy="1.5708 1.8849 0" xyz="0.461 0 2.103"/>
    <parent link="base_link"/>
    <child link="_bodycenter"/>
  </joint>
  <joint name="_depth_joint" type="fixed">
    <origin rpy="0 0 0" xyz="0.049 0 0"/>
    <parent link="_bodycenter"/>
    <child link="_depth_frame"/>
  </joint>
  <link name="_depth_frame"/>
  <joint name="_rgb_joint" type="fixed">
    <origin rpy="0 0 0" xyz="0.022 0 0"/>
    <parent link="_bodycenter"/>
    <child link="_rgb_frame"/>
  </joint>
  <link name="_rgb_frame"/>
  <link name="base_link"> </link>
  <link name="frame_left">
    <visual>
      <origin rpy="0 0 0" xyz="0 0 0"/>
      <geometry>
        <mesh filename="package://euler_support/meshes/visual/frame_left.stl"/>
      </geometry>
      <material name="">
        <color rgba="0.752941176470588 0.752941176470588 0.752941176470588 1"/>
      </material>
    </visual>
    <collision>
      <origin rpy="0 0 0" xyz="0 0 0"/>
      <geometry>
        <mesh filename="package://euler_support/meshes/collision/frame_left.stl"/>
      </geometry>
    </collision>
  </link>
  <link name="frame_right">
    <visual>
      <origin rpy="0 0 0" xyz="0 0 0"/>
      <geometry>
        <mesh filename="package://euler_support/meshes/visual/frame_right.stl"/>
      </geometry>
      <material name="">
        <color rgba="0.752941176470588 0.752941176470588 0.752941176470588 1"/>
      </material>
    </visual>
    <collision>
      <origin rpy="0 0 0" xyz="0 0 0"/>
      <geometry>
        <mesh filename="package://euler_support/meshes/collision/frame_right.stl"/>
      </geometry>
    </collision>
  </link>
  <link name="frame_top">
    <visual>
      <origin rpy="0 0 0" xyz="0 0 0"/>
      <geometry>
        <mesh filename="package://euler_support/meshes/visual/frame_top.stl"/>
      </geometry>
      <material name="">
        <color rgba="0.752941176470588 0.752941176470588 0.752941176470588 1"/>
      </material>
    </visual>
    <collision>
      <origin rpy="0 0 0" xyz="0 0 0"/>
      <geometry>
        <mesh filename="package://euler_support/meshes/collision/frame_top.stl"/>
      </geometry>
    </collision>
  </link>
  <link name="sick_nav350">
    <visual>
      <origin rpy="0 0 0" xyz="-0.239 -0.648 2.551"/>
      <geometry>
        <mesh filename="package://euler_support/meshes/visual/sick_nav350.stl"/>
      </geometry>
      <material name="">
        <color rgba="0 0 0.752941176470588 1"/>
      </material>
    </visual>
    <collision>
      <origin rpy="0 0 0" xyz="-0.239 -0.648 2.551"/>
      <geometry>
        <mesh filename="package://euler_support/meshes/collision/sick_nav350.stl"/>
      </geometry>
    </collision>
  </link>
  <link name="front_sick_s300">
    <visual>
      <origin rpy="0 0 -0.75047" xyz="0.193 -0.617 0.532"/>
      <geometry>
        <mesh filename="package://euler_support/meshes/visual/sick_s300_mounting_assy.stl"/>
      </geometry>
      <material name="">
        <color rgba="0.75 0.75 0 1"/>
      </material>
    </visual>
    <collision>
      <origin rpy="0 0 -0.75047" xyz="0.193 0.617 0.532"/>
      <geometry>
        <mesh filename="package://euler_support/meshes/collision/sick_s300_mounting_assy.stl"/>
      </geometry>
    </collision>
  </link>
  <link name="rear_sick_s300">
    <visual>
      <origin rpy="0 0  -3.96178" xyz="-2.280 0.617 0.532"/>
      <geometry>
        <mesh filename="package://euler_support/meshes/visual/sick_s300_mounting_assy.stl"/>
      </geometry>
      <material name="">
        <color rgba="0.75 0.75 0 1"/>
      </material>
    </visual>
    <collision>
      <origin rpy="0 0 -3.96178" xyz="-2.280 -0.617 0.532"/>
      <geometry>
        <mesh filename="package://euler_support/meshes/collision/sick_s300_mounting_assy.stl"/>
      </geometry>
    </collision>
  </link>
  <joint name="frame_left" type="fixed">
    <parent link="base_link"/>
    <child link="frame_left"/>
    <origin rpy="0 0 0" xyz="0 0 0"/>
    <axis xyz="0 0 0"/>
  </joint>
  <joint name="frame_right" type="fixed">
    <parent link="base_link"/>
    <child link="frame_right"/>
    <origin rpy="0 0 0" xyz="0 0 0"/>
    <axis xyz="0 0 0"/>
  </joint>
  <joint name="frame_top" type="fixed">
    <parent link="base_link"/>
    <child link="frame_top"/>
    <origin rpy="0 0 0" xyz="0 0 0"/>
    <axis xyz="0 0 0"/>
  </joint>
  <joint name="to_vetex" type="fixed">
    <parent link="base_link"/>
    <child link="vetex_base_link"/>
    <origin rpy="0 0 0" xyz="0 0 0"/>
    <axis xyz="0 0 0"/>
  </joint>
  <joint name="to_arm" type="fixed">
    <parent link="base_link"/>
    <child link="motoman_base_link"/>
    <origin rpy="3.1415 0 0" xyz="0.067518 0 2.016"/>
    <axis xyz="0 0 0"/>
  </joint>
  <joint name="sick_nav350" type="fixed">
    <parent link="base_link"/>
    <child link="sick_nav350"/>
    <origin rpy="0 0 0" xyz="0 0 0"/>
    <axis xyz="0 0 0"/>
  </joint>
  <joint name="front_sick_s300" type="fixed">
    <parent link="base_link"/>
    <child link="front_sick_s300"/>
    <origin rpy="0 0 0" xyz="0 0 0"/>
    <axis xyz="0 0 0"/>
  </joint>
  <joint name="rear_sick_s300" type="fixed">
    <parent link="base_link"/>
    <child link="rear_sick_s300"/>
    <origin rpy="0 0 0" xyz="0 0 0"/>
    <axis xyz="0 0 0"/>
  </joint>
</robot>

