<?xml version="1.0" ?>
<!-- =================================================================================== -->
<!-- |    This document was autogenerated by xacro from vetex.xacro                    | -->
<!-- |    EDITING THIS FILE BY HAND IS NOT RECOMMENDED                                 | -->
<!-- =================================================================================== -->
<robot name="vetex" xmlns:xacro="http://ros.org/wiki/xacro">
  <link name="base_link">
    <visual>
      <origin rpy="0 0 0"/>
      <geometry>
        <mesh filename="package://vetex_support/meshes/visual/base_link.stl"/>
      </geometry>
      <material name="">
        <color rgba="0.75294 0.75294 0.75294 1"/>
      </material>
    </visual>
    <collision>
      <origin rpy="0 0 0" xyz="0 0 0"/>
      <geometry>
        <mesh filename="package://vetex_support/meshes/collision/base_link.stl"/>
      </geometry>
    </collision>
  </link>
  <link name="map">
    <visual>
      <origin rpy="0 0 0" xyz="0 0 0"/>
      <geometry>
        <mesh filename="package://vetex_support/meshes/visual/map.stl"/>
      </geometry>
      <material name="">
        <color rgba="0.75294 0.75294 0.75294 1"/>
      </material>
    </visual>
    <collision>
      <origin Rpy="0 0 0" xyz="0 0 0"/>
      <geometry>
        <mesh filename="package://vetex_support/meshes/collision/map.stl"/>
      </geometry>
    </collision>
  </link>
  <link name="odom">
    <visual>
      <origin rpy="0 0 0" xyz="0 0 0"/>
      <geometry>
        <mesh filename="package://vetex_support/meshes/visual/odom.stl"/>
      </geometry>
      <material name="">
        <color rgba="0.75294 0.75294 0.75294 1"/>
      </material>
    </visual>
    <collision>
      <origin rpy="0 0 0" xyz="0 0 0"/>
      <geometry>
        <mesh filename="package://vetex_support/meshes/collision/odom.stl"/>
      </geometry>
    </collision>
  </link>
  <link name="left_front_wheel">
    <visual>
      <origin rpy="0 0 0" xyz="0 0 0"/>
      <geometry>
        <mesh filename="package://vetex_support/meshes/visual/left_front_wheel.stl"/>
      </geometry>
      <material name="">
        <color rgba="0.75294 0.75294 0.75294 1"/>
      </material>
    </visual>
    <collision>
      <origin rpy="0 0 0" xyz="0 0 0"/>
      <geometry>
        <mesh filename="package://vetex_support/meshes/collision/left_front_wheel.stl"/>
      </geometry>
    </collision>
  </link>
  <link name="left_rear_wheel">
    <visual>
      <origin rpy="0 0 0" xyz="0 0 0"/>
      <geometry>
        <mesh filename="package://vetex_support/meshes/visual/left_rear_wheel.stl"/>
      </geometry>
      <material name="">
        <color rgba="0.75294 0.75294 0.75294 1"/>
      </material>
    </visual>
    <collision>
      <origin rpy="0 0 0" xyz="0 0 0"/>
      <geometry>
        <mesh filename="package://vetex_support/meshes/collision/left_rear_wheel.stl"/>
      </geometry>
    </collision>
  </link>
  <link name="right_rear_wheel">
    <visual>
      <origin rpy="3.1415 0 0" xyz="0 0 0"/>
      <geometry>
        <mesh filename="package://vetex_support/meshes/visual/right_rear_wheel.stl"/>
      </geometry>
      <material name="">
        <color rgba="0.75294 0.75294 0.75294 1"/>
      </material>
    </visual>
    <collision>
      <origin rpy="3.1415 0 0" xyz="0 0 0"/>
      <geometry>
        <mesh filename="package://vetex_support/meshes/collision/right_rear_wheel.stl"/>
      </geometry>
    </collision>
  </link>
  <link name="right_front_wheel">
    <visual>
      <origin rpy="3.1415 0 0" xyz="0 0 0"/>
      <geometry>
        <mesh filename="package://vetex_support/meshes/visual/right_front_wheel.stl"/>
      </geometry>
      <material name="">
        <color rgba="0.75294 0.75294 0.75294 1"/>
      </material>
    </visual>
    <collision>
      <origin rpy="3.1415 0 0" xyz="0 0 0"/>
      <geometry>
        <mesh filename="package://vetex_support/meshes/collision/right_front_wheel.stl"/>
      </geometry>
    </collision>
  </link>
  <joint name="map" type="fixed">
    <origin rpy="0 0 0" xyz="0 0 0"/>
    <parent link="base_link"/>
    <child link="map"/>
    <axis xyz="0 0 0"/>
  </joint>
  <joint name="odom" type="fixed">
    <origin rpy="0 0 0" xyz="0 0 0"/>
    <parent link="map"/>
    <child link="odom"/>
    <axis xyz="0 0 0"/>
  </joint>
  <joint name="left_front_wheel" type="revolute">
    <origin rpy="0 1 0" xyz="0 0.58668 0.21577"/>
    <parent link="odom"/>
    <child link="left_front_wheel"/>
    <axis xyz="0 1 0"/>
    <limit effort="0" lower="-10" upper="10" velocity="3"/>
  </joint>
  <joint name="left_rear_wheel" type="revolute">
    <origin rpy="0 1 0" xyz="-2.0878 0.58642 0.21577"/>
    <parent link="odom"/>
    <child link="left_rear_wheel"/>
    <axis xyz="0 1 0"/>
    <limit effort="0" lower="-10" upper="10" velocity="3"/>
  </joint>
  <joint name="right_rear_wheel" type="revolute">
    <origin rpy="0 1 0" xyz="-2.0878 -0.58668 0.21577"/>
    <parent link="odom"/>
    <child link="right_rear_wheel"/>
    <axis xyz="0 1 0"/>
    <limit effort="0" lower="-10" upper="10" velocity="3"/>
  </joint>
  <joint name="right_front_wheel" type="revolute">
    <origin rpy="0 0 0" xyz="0 -0.58642 0.21577"/>
    <parent link="odom"/>
    <child link="right_front_wheel"/>
    <axis xyz="0 1 0"/>
    <limit effort="0" lower="-10" upper="10" velocity="3"/>
  </joint>
</robot>

