<?xml version="1.0" ?>
<!-- =================================================================================== -->
<!-- |    This document was autogenerated by xacro from mh5lf.xacro                    | -->
<!-- |    EDITING THIS FILE BY HAND IS NOT RECOMMENDED                                 | -->
<!-- =================================================================================== -->
<robot name="motoman_mh5lf" xmlns:xacro="http://ros.org/wiki/xacro">
  <link name="base_link">
    <visual>
      <origin rpy="0 0 0"/>
      <geometry>
        <mesh filename="package://motoman_mh5lf_support/meshes/mh5lf/visual/base_link.stl"/>
      </geometry>
      <material name="blue">
        <color rgba="0 0 1 1"/>
      </material>
    </visual>
    <collision>
      <origin rpy="0 0 0"/>
      <geometry>
        <mesh filename="package://motoman_mh5lf_support/meshes/mh5lf/collision/base_link.stl"/>
      </geometry>
      <material name="yellow">
        <color rgba="0 1 1 1"/>
      </material>
    </collision>
  </link>
  <link name="link_s">
    <visual>
      <geometry>
        <mesh filename="package://motoman_mh5lf_support/meshes/mh5lf/visual/link_s.stl"/>
      </geometry>
      <material name="silver">
        <color rgba="0.8 0.8 0.8 1"/>
      </material>
    </visual>
    <collision>
      <geometry>
        <mesh filename="package://motoman_mh5lf_support/meshes/mh5lf/collision/link_s.stl"/>
      </geometry>
      <material name="yellow"/>
    </collision>
  </link>
  <link name="link_l">
    <visual>
      <geometry>
        <mesh filename="package://motoman_mh5lf_support/meshes/mh5lf/visual/link_l.stl"/>
      </geometry>
      <material name="blue"/>
    </visual>
    <collision>
      <geometry>
        <mesh filename="package://motoman_mh5lf_support/meshes/mh5lf/collision/link_l.stl"/>
      </geometry>
      <material name="yellow"/>
    </collision>
  </link>
  <link name="link_u">
    <visual>
      <geometry>
        <mesh filename="package://motoman_mh5lf_support/meshes/mh5lf/visual/link_u.stl"/>
      </geometry>
      <material name="blue"/>
    </visual>
    <collision>
      <geometry>
        <mesh filename="package://motoman_mh5lf_support/meshes/mh5lf/collision/link_u.stl"/>
      </geometry>
      <material name="yellow"/>
    </collision>
  </link>
  <link name="link_r">
    <visual>
      <geometry>
        <mesh filename="package://motoman_mh5lf_support/meshes/mh5lf/visual/link_r.stl"/>
      </geometry>
      <material name="silver"/>
    </visual>
    <collision>
      <geometry>
        <mesh filename="package://motoman_mh5lf_support/meshes/mh5lf/collision/link_r.stl"/>
      </geometry>
      <material name="yellow"/>
    </collision>
  </link>
  <link name="link_b">
    <visual>
      <geometry>
        <mesh filename="package://motoman_mh5lf_support/meshes/mh5lf/visual/link_b.stl"/>
      </geometry>
      <material name="blue"/>
    </visual>
    <collision>
      <geometry>
        <mesh filename="package://motoman_mh5lf_support/meshes/mh5lf/collision/link_b.stl"/>
      </geometry>
      <material name="yellow"/>
    </collision>
  </link>
  <link name="link_t">
    <visual>
      <geometry>
        <mesh filename="package://motoman_mh5lf_support/meshes/mh5lf/visual/link_t.stl"/>
      </geometry>
      <material name="silver"/>
    </visual>
    <collision>
      <geometry>
        <mesh filename="package://motoman_mh5lf_support/meshes/mh5lf/collision/link_t.stl"/>
      </geometry>
      <material name="yellow"/>
    </collision>
  </link>
  <joint name="joint_s" type="revolute">
    <parent link="base_link"/>
    <child link="link_s"/>
    <origin rpy="0 0 0" xyz="0 0 0"/>
    <axis xyz="0 0 1"/>
    <limit effort="100" lower="-2.96697222222222" upper="2.96697222222222" velocity="4.71225"/>
  </joint>
  <joint name="joint_l" type="revolute">
    <parent link="link_s"/>
    <child link="link_l"/>
    <origin rpy="0 0 0" xyz="0.088 0 0.36"/>
    <axis xyz="0 1 0"/>
    <limit effort="100" lower="-1.13443055555556" upper="2.61791666666667" velocity="4.88677777777778"/>
  </joint>
  <joint name="joint_u" type="revolute">
    <parent link="link_l"/>
    <child link="link_u"/>
    <origin rpy="0 0 0" xyz="0 0 0.4"/>
    <axis xyz="0 -1 0"/>
    <limit effort="100" lower="-2.40848333333333" upper="4.45045833333333" velocity="5.23583333333333"/>
  </joint>
  <joint name="joint_r" type="revolute">
    <parent link="link_u"/>
    <child link="link_r"/>
    <origin rpy="0 0 0" xyz="0 0 0.04"/>
    <axis xyz="-1 0 0"/>
    <limit effort="100" lower="-3.31602777777778" upper="3.31602777777778" velocity="7.85375"/>
  </joint>
  <joint name="joint_b" type="revolute">
    <parent link="link_r"/>
    <child link="link_b"/>
    <origin rpy="0 0 0" xyz="0.404 0 0"/>
    <axis xyz="0 -1 0"/>
    <limit effort="100" lower="-2.356125" upper="2.356125" velocity="7.85375"/>
  </joint>
  <joint name="joint_t" type="revolute">
    <parent link="link_b"/>
    <child link="link_t"/>
    <origin rpy="0 0 0" xyz="0 0 0"/>
    <axis xyz="-1 0 0"/>
    <limit effort="100" lower="-6.283" upper="6.283" velocity="12.566"/>
  </joint>
</robot>

