<?xml version="1.0" ?>
<robot xmlns:xacro="http://ros.org/wiki/xacro">
	<xacro:macro name="motoman_mh5lf" params="prefix">
		<!-- link list -->
		<link name="${prefix}base_link">
			<visual>
			        <origin rpy="0 0 0"/>
				<geometry>
					<mesh filename="package://motoman_mh5lf_support/meshes/mh5lf/visual/base_link.stl" />
				</geometry>
				<material name="blue">
					<color rgba="0 0 1 1"/>
				</material>
			</visual>
			<collision>
			        <origin rpy="0 0 0"/>
				<geometry>
					<mesh filename="package://motoman_mh5lf_support/meshes/mh5lf/collision/base_link.stl" />
				</geometry>
				<material name="yellow">
					<color rgba="0 1 1 1"/>
				</material>
			</collision>
		</link>
		<link name="${prefix}link_s">
			<visual>
				<geometry>
					<mesh filename="package://motoman_mh5lf_support/meshes/mh5lf/visual/link_s.stl"/>
				</geometry>
				<material name="silver">
					<color rgba="0.8 0.8 0.8 1"/>
				</material>
			</visual>
			<collision>
				<geometry>
					<mesh filename="package://motoman_mh5lf_support/meshes/mh5lf/collision/link_s.stl" />
				</geometry>
				<material name="yellow"/>
			</collision>
		</link>
		<link name="${prefix}link_l">
			<visual>
				<geometry>
					<mesh filename="package://motoman_mh5lf_support/meshes/mh5lf/visual/link_l.stl"/>
				</geometry>
				<material name="blue"/>
			</visual>
			<collision>
				<geometry>
					<mesh filename="package://motoman_mh5lf_support/meshes/mh5lf/collision/link_l.stl" />
				</geometry>
				<material name="yellow"/>
			</collision>
		</link>
		<link name="${prefix}link_u">
			<visual>
				<geometry>
					<mesh filename="package://motoman_mh5lf_support/meshes/mh5lf/visual/link_u.stl"/>
				</geometry>
				<material name="blue"/>
			</visual>
			<collision>
				<geometry>
					<mesh filename="package://motoman_mh5lf_support/meshes/mh5lf/collision/link_u.stl" />
				</geometry>
				<material name="yellow"/>
			</collision>
		</link>
		<link name="${prefix}link_r">
			<visual>
				<geometry>
					<mesh filename="package://motoman_mh5lf_support/meshes/mh5lf/visual/link_r.stl"/>
				</geometry>
				<material name="silver"/>
			</visual>
			<collision>
				<geometry>
					<mesh filename="package://motoman_mh5lf_support/meshes/mh5lf/collision/link_r.stl" />
				</geometry>
				<material name="yellow"/>
			</collision>
		</link>
		<link name="${prefix}link_b">
			<visual>
				<geometry>
					<mesh filename="package://motoman_mh5lf_support/meshes/mh5lf/visual/link_b.stl"/>
				</geometry>
				<material name="blue"/>
			</visual>
			<collision>
				<geometry>
					<mesh filename="package://motoman_mh5lf_support/meshes/mh5lf/collision/link_b.stl" />
				</geometry>
				<material name="yellow"/>
			</collision>
		</link>
		<link name="${prefix}link_t">
			<visual>
				<geometry>
					<mesh filename="package://motoman_mh5lf_support/meshes/mh5lf/visual/link_t.stl" />
				</geometry>
				<material name="silver"/>
			</visual>
			<collision>
				<geometry>
					<mesh filename="package://motoman_mh5lf_support/meshes/mh5lf/collision/link_t.stl" />
				</geometry>
				<material name="yellow"/>
			</collision>
		</link>
		<!-- end of link list -->
		<!-- joint list -->
		<joint name="${prefix}joint_s" type="revolute">
			<parent link="${prefix}base_link"/>
			<child link="${prefix}link_s"/>
			<origin xyz="0 0 0" rpy="0 0 0"/>
			<axis xyz="0 0 1" />
			 <limit lower="-2.96697222222222" upper="2.96697222222222" effort="100" velocity="4.71225" />
		</joint>
		<joint name="${prefix}joint_l" type="revolute">
			<parent link="${prefix}link_s"/>
			<child link="${prefix}link_l"/>
			<origin xyz="0.088 0 0.36" rpy="0 0 0"/>
			<axis xyz="0 1 0" />
			<limit lower="-1.13443055555556" upper="2.61791666666667" effort="100" velocity="4.88677777777778" />
		</joint>
		<joint name="${prefix}joint_u" type="revolute">
			<parent link="${prefix}link_l"/>
			<child link="${prefix}link_u"/>
			<origin xyz="0 0 0.4" rpy="0 0 0"/>
			<axis xyz="0 -1 0" />
			<limit lower="-2.40848333333333" upper="4.45045833333333" effort="100" velocity="5.23583333333333" />
		</joint>
		<joint name="${prefix}joint_r" type="revolute">
			<parent link="${prefix}link_u"/>
			<child link="${prefix}link_r"/>
			<origin xyz="0 0 0.04" rpy="0 0 0"/>
			<axis xyz="-1 0 0" />
			<limit lower="-3.31602777777778" upper="3.31602777777778" effort="100" velocity="7.85375" />
		</joint>
		<joint name="${prefix}joint_b" type="revolute">
			<parent link="${prefix}link_r"/>
			<child link="${prefix}link_b"/>
			<origin xyz="0.404 0 0" rpy="0 0 0"/>
			<axis xyz="0 -1 0" />
			<limit lower="-2.356125" upper="2.356125" effort="100" velocity="7.85375" />
		</joint>
		<joint name="${prefix}joint_t" type="revolute">
			<parent link="${prefix}link_b"/>
			<child link="${prefix}link_t"/>
			<origin xyz="0 0 0" rpy="0 0 0"/>
			<axis xyz="-1 0 0" />
			<limit lower="-6.283" upper="6.283" effort="100" velocity="12.566" />
		</joint>
		<!-- end of joint list -->
	</xacro:macro>
</robot>

